/content/drive/MyDrive/research_discourse_relation/discourse_relation_explainability
Traceback (most recent call last):
  File "/usr/lib/python3.10/argparse.py", line 2507, in _get_value
    result = type_func(arg_string)
  File "/usr/local/lib/python3.10/dist-packages/tap/utils.py", line 292, in var_type
    raise ArgumentTypeError(f'Value for variable "{variable}" must be one of {literals}.')
argparse.ArgumentTypeError: Value for variable "experiment_type" must be one of ['normal', 'ordinal_forms', 'ordinal_forms_shuffle', 'pos_sequence'].
During handling of the above exception, another exception occurred:
Traceback (most recent call last):
  File "/usr/lib/python3.10/argparse.py", line 1878, in parse_known_args
    namespace, args = self._parse_known_args(args, namespace)
  File "/usr/lib/python3.10/argparse.py", line 2091, in _parse_known_args
    start_index = consume_optional(start_index)
  File "/usr/lib/python3.10/argparse.py", line 2031, in consume_optional
    take_action(action, args, option_string)
  File "/usr/lib/python3.10/argparse.py", line 1939, in take_action
    argument_values = self._get_values(action, argument_strings)
  File "/usr/lib/python3.10/argparse.py", line 2474, in _get_values
    value = self._get_value(action, arg_string)
  File "/usr/lib/python3.10/argparse.py", line 2513, in _get_value
    raise ArgumentError(action, msg)
argparse.ArgumentError: argument --experiment_type: Value for variable "experiment_type" must be one of ['normal', 'ordinal_forms', 'ordinal_forms_shuffle', 'pos_sequence'].
During handling of the above exception, another exception occurred:
Traceback (most recent call last):
  File "/usr/local/lib/python3.10/dist-packages/IPython/core/interactiveshell.py", line 3553, in run_code
    exec(code_obj, self.user_global_ns, self.user_ns)
  File "<ipython-input-88-0d928a305615>", line 1, in <cell line: 1>
    args = Args().parse_args([
  File "/usr/local/lib/python3.10/dist-packages/tap/tap.py", line 451, in parse_args
    default_namespace = super(Tap, self).parse_args(args)
  File "/usr/lib/python3.10/argparse.py", line 1845, in parse_args
    args, argv = self.parse_known_args(args, namespace)
  File "/usr/lib/python3.10/argparse.py", line 1881, in parse_known_args
    self.error(str(err))
  File "/usr/lib/python3.10/argparse.py", line 2606, in error
    self.exit(2, _('%(prog)s: error: %(message)s\n') % args)
  File "/usr/lib/python3.10/argparse.py", line 2593, in exit
    _sys.exit(status)
  File "/usr/local/lib/python3.10/dist-packages/wandb/sdk/lib/exit_hooks.py", line 36, in exit
    self._orig_exit(orig_code)  # type: ignore
SystemExit: 2
During handling of the above exception, another exception occurred:
Traceback (most recent call last):
  File "/usr/local/lib/python3.10/dist-packages/IPython/core/ultratb.py", line 1101, in get_records
    return _fixed_getinnerframes(etb, number_of_lines_of_context, tb_offset)
  File "/usr/local/lib/python3.10/dist-packages/IPython/core/ultratb.py", line 248, in wrapped
    return f(*args, **kwargs)
  File "/usr/local/lib/python3.10/dist-packages/IPython/core/ultratb.py", line 281, in _fixed_getinnerframes
    records = fix_frame_records_filenames(inspect.getinnerframes(etb, context))
  File "/usr/lib/python3.10/inspect.py", line 1662, in getinnerframes
    frameinfo = (tb.tb_frame,) + getframeinfo(tb, context)
AttributeError: 'tuple' object has no attribute 'tb_frame'
usage: colab_kernel_launcher.py [--model_name MODEL_NAME] [--dataset_dir DATASET_DIR]
                                [--batch_size BATCH_SIZE] [--epochs EPOCHS] [--lr LR]
                                [--num_warmup_epochs NUM_WARMUP_EPOCHS]
                                [--max_seq_len MAX_SEQ_LEN] [--weight_decay WEIGHT_DECAY]
                                [--gradient_checkpointing] --experiment_type
                                {normal,ordinal_forms,ordinal_forms_shuffle,pos_sequence}
                                [--device DEVICE] [--seed SEED] [--should_save_model] [-h]
colab_kernel_launcher.py: error: argument --experiment_type: Value for variable "experiment_type" must be one of ['normal', 'ordinal_forms', 'ordinal_forms_shuffle', 'pos_sequence'].
ERROR:root:Internal Python error in the inspect module.
Below is the traceback from this internal error.
Drive already mounted at /content/drive; to attempt to forcibly remount, call drive.mount("/content/drive", force_remount=True).
/content/drive/MyDrive/research_discourse_relation/discourse_relation_explainability
/sbin/ldconfig.real: /usr/local/lib/libtbbbind_2_0.so.3 is not a symbolic link
/sbin/ldconfig.real: /usr/local/lib/libtbbbind_2_5.so.3 is not a symbolic link
/sbin/ldconfig.real: /usr/local/lib/libtbbmalloc_proxy.so.2 is not a symbolic link
/sbin/ldconfig.real: /usr/local/lib/libtbb.so.12 is not a symbolic link
/sbin/ldconfig.real: /usr/local/lib/libtbbbind.so.3 is not a symbolic link
/sbin/ldconfig.real: /usr/local/lib/libtbbmalloc.so.2 is not a symbolic link
Requirement already satisfied: typed-argument-parser in /usr/local/lib/python3.10/dist-packages (1.10.0)
Requirement already satisfied: typing-inspect>=0.7.1 in /usr/local/lib/python3.10/dist-packages (from typed-argument-parser) (0.9.0)
Requirement already satisfied: docstring-parser>=0.15 in /usr/local/lib/python3.10/dist-packages (from typed-argument-parser) (0.16)
Requirement already satisfied: mypy-extensions>=0.3.0 in /usr/local/lib/python3.10/dist-packages (from typing-inspect>=0.7.1->typed-argument-parser) (1.0.0)
Requirement already satisfied: typing-extensions>=3.7.4 in /usr/local/lib/python3.10/dist-packages (from typing-inspect>=0.7.1->typed-argument-parser) (4.11.0)
Traceback (most recent call last):
  File "/usr/local/lib/python3.10/dist-packages/pip/_vendor/pkg_resources/__init__.py", line 3108, in _dep_map
    return self.__dep_map
  File "/usr/local/lib/python3.10/dist-packages/pip/_vendor/pkg_resources/__init__.py", line 2901, in __getattr__
    raise AttributeError(attr)
AttributeError: _DistInfoDistribution__dep_map
During handling of the above exception, another exception occurred:
Traceback (most recent call last):
  File "/usr/local/lib/python3.10/dist-packages/pip/_internal/cli/base_command.py", line 169, in exc_logging_wrapper
    status = run_func(*args)
  File "/usr/local/lib/python3.10/dist-packages/pip/_internal/cli/req_command.py", line 242, in wrapper
    return func(self, options, args)
  File "/usr/local/lib/python3.10/dist-packages/pip/_internal/commands/install.py", line 441, in run
    conflicts = self._determine_conflicts(to_install)
  File "/usr/local/lib/python3.10/dist-packages/pip/_internal/commands/install.py", line 572, in _determine_conflicts
    return check_install_conflicts(to_install)
  File "/usr/local/lib/python3.10/dist-packages/pip/_internal/operations/check.py", line 101, in check_install_conflicts
    package_set, _ = create_package_set_from_installed()
  File "/usr/local/lib/python3.10/dist-packages/pip/_internal/operations/check.py", line 42, in create_package_set_from_installed
    dependencies = list(dist.iter_dependencies())
  File "/usr/local/lib/python3.10/dist-packages/pip/_internal/metadata/pkg_resources.py", line 216, in iter_dependencies
    return self._dist.requires(extras)
  File "/usr/local/lib/python3.10/dist-packages/pip/_vendor/pkg_resources/__init__.py", line 2821, in requires
    dm = self._dep_map
  File "/usr/local/lib/python3.10/dist-packages/pip/_vendor/pkg_resources/__init__.py", line 3110, in _dep_map
    self.__dep_map = self._compute_dependencies()
  File "/usr/local/lib/python3.10/dist-packages/pip/_vendor/pkg_resources/__init__.py", line 3132, in _compute_dependencies
    dm[s_extra] = [r for r in reqs_for_extra(extra) if r not in common]
  File "/usr/local/lib/python3.10/dist-packages/pip/_vendor/pkg_resources/__init__.py", line 3132, in <listcomp>
    dm[s_extra] = [r for r in reqs_for_extra(extra) if r not in common]
  File "/usr/local/lib/python3.10/dist-packages/pip/_vendor/pkg_resources/__init__.py", line 3124, in reqs_for_extra
    if not req.marker or req.marker.evaluate({'extra': extra}):
  File "/usr/local/lib/python3.10/dist-packages/pip/_vendor/packaging/markers.py", line 300, in evaluate
    current_environment = default_environment()
  File "/usr/local/lib/python3.10/dist-packages/pip/_vendor/packaging/markers.py", line 266, in default_environment
    "platform_system": platform.system(),
  File "/usr/lib/python3.10/platform.py", line 903, in system
    def system():
KeyboardInterrupt
During handling of the above exception, another exception occurred:
Traceback (most recent call last):
  File "/usr/local/bin/pip3", line 8, in <module>
    sys.exit(main())
  File "/usr/local/lib/python3.10/dist-packages/pip/_internal/cli/main.py", line 79, in main
    return command.main(cmd_args)
  File "/usr/local/lib/python3.10/dist-packages/pip/_internal/cli/base_command.py", line 101, in main
    return self._main(args)
  File "/usr/local/lib/python3.10/dist-packages/pip/_internal/cli/base_command.py", line 223, in _main
    return run(options, args)
  File "/usr/local/lib/python3.10/dist-packages/pip/_internal/cli/base_command.py", line 206, in exc_logging_wrapper
    logger.critical("Operation cancelled by user")
  File "/usr/lib/python3.10/logging/__init__.py", line 1524, in critical
    self._log(CRITICAL, msg, args, **kwargs)
  File "/usr/lib/python3.10/logging/__init__.py", line 1622, in _log
    record = self.makeRecord(self.name, level, fn, lno, msg, args,
  File "/usr/lib/python3.10/logging/__init__.py", line 1591, in makeRecord
    rv = _logRecordFactory(name, level, fn, lno, msg, args, exc_info, func,
  File "/usr/lib/python3.10/logging/__init__.py", line 313, in __init__
    self.levelname = getLevelName(level)
  File "/usr/lib/python3.10/logging/__init__.py", line 119, in getLevelName
    def getLevelName(level):
KeyboardInterrupt
^C
Requirement already satisfied: transformers in /usr/local/lib/python3.10/dist-packages (4.40.1)
Requirement already satisfied: filelock in /usr/local/lib/python3.10/dist-packages (from transformers) (3.14.0)
Requirement already satisfied: huggingface-hub<1.0,>=0.19.3 in /usr/local/lib/python3.10/dist-packages (from transformers) (0.20.3)
Requirement already satisfied: numpy>=1.17 in /usr/local/lib/python3.10/dist-packages (from transformers) (1.25.2)
Requirement already satisfied: packaging>=20.0 in /usr/local/lib/python3.10/dist-packages (from transformers) (24.0)
Requirement already satisfied: pyyaml>=5.1 in /usr/local/lib/python3.10/dist-packages (from transformers) (6.0.1)
Requirement already satisfied: regex!=2019.12.17 in /usr/local/lib/python3.10/dist-packages (from transformers) (2023.12.25)
Requirement already satisfied: requests in /usr/local/lib/python3.10/dist-packages (from transformers) (2.31.0)
Requirement already satisfied: tokenizers<0.20,>=0.19 in /usr/local/lib/python3.10/dist-packages (from transformers) (0.19.1)
Requirement already satisfied: safetensors>=0.4.1 in /usr/local/lib/python3.10/dist-packages (from transformers) (0.4.3)
Requirement already satisfied: tqdm>=4.27 in /usr/local/lib/python3.10/dist-packages (from transformers) (4.66.2)
Requirement already satisfied: fsspec>=2023.5.0 in /usr/local/lib/python3.10/dist-packages (from huggingface-hub<1.0,>=0.19.3->transformers) (2023.6.0)
Requirement already satisfied: typing-extensions>=3.7.4.3 in /usr/local/lib/python3.10/dist-packages (from huggingface-hub<1.0,>=0.19.3->transformers) (4.11.0)
Requirement already satisfied: charset-normalizer<4,>=2 in /usr/local/lib/python3.10/dist-packages (from requests->transformers) (3.3.2)
Requirement already satisfied: idna<4,>=2.5 in /usr/local/lib/python3.10/dist-packages (from requests->transformers) (3.7)
Requirement already satisfied: urllib3<3,>=1.21.1 in /usr/local/lib/python3.10/dist-packages (from requests->transformers) (2.0.7)
Requirement already satisfied: certifi>=2017.4.17 in /usr/local/lib/python3.10/dist-packages (from requests->transformers) (2024.2.2)
Traceback (most recent call last):
  File "/usr/local/lib/python3.10/dist-packages/pip/_vendor/pkg_resources/__init__.py", line 3108, in _dep_map
    return self.__dep_map
  File "/usr/local/lib/python3.10/dist-packages/pip/_vendor/pkg_resources/__init__.py", line 2901, in __getattr__
    raise AttributeError(attr)
AttributeError: _DistInfoDistribution__dep_map
During handling of the above exception, another exception occurred:
Traceback (most recent call last):
  File "/usr/local/lib/python3.10/dist-packages/pip/_vendor/pkg_resources/__init__.py", line 3099, in _parsed_pkg_info
    return self._pkg_info
  File "/usr/local/lib/python3.10/dist-packages/pip/_vendor/pkg_resources/__init__.py", line 2901, in __getattr__
    raise AttributeError(attr)
AttributeError: _pkg_info. Did you mean: 'egg_info'?
During handling of the above exception, another exception occurred:
Traceback (most recent call last):
  File "/usr/local/lib/python3.10/dist-packages/pip/_internal/cli/base_command.py", line 169, in exc_logging_wrapper
    status = run_func(*args)
  File "/usr/local/lib/python3.10/dist-packages/pip/_internal/cli/req_command.py", line 242, in wrapper
    return func(self, options, args)
  File "/usr/local/lib/python3.10/dist-packages/pip/_internal/commands/install.py", line 441, in run
    conflicts = self._determine_conflicts(to_install)
  File "/usr/local/lib/python3.10/dist-packages/pip/_internal/commands/install.py", line 572, in _determine_conflicts
    return check_install_conflicts(to_install)
  File "/usr/local/lib/python3.10/dist-packages/pip/_internal/operations/check.py", line 101, in check_install_conflicts
    package_set, _ = create_package_set_from_installed()
  File "/usr/local/lib/python3.10/dist-packages/pip/_internal/operations/check.py", line 42, in create_package_set_from_installed
    dependencies = list(dist.iter_dependencies())
  File "/usr/local/lib/python3.10/dist-packages/pip/_internal/metadata/pkg_resources.py", line 216, in iter_dependencies
    return self._dist.requires(extras)
  File "/usr/local/lib/python3.10/dist-packages/pip/_vendor/pkg_resources/__init__.py", line 2821, in requires
    dm = self._dep_map
  File "/usr/local/lib/python3.10/dist-packages/pip/_vendor/pkg_resources/__init__.py", line 3110, in _dep_map
    self.__dep_map = self._compute_dependencies()
  File "/usr/local/lib/python3.10/dist-packages/pip/_vendor/pkg_resources/__init__.py", line 3119, in _compute_dependencies
    for req in self._parsed_pkg_info.get_all('Requires-Dist') or []:
  File "/usr/local/lib/python3.10/dist-packages/pip/_vendor/pkg_resources/__init__.py", line 3102, in _parsed_pkg_info
    self._pkg_info = email.parser.Parser().parsestr(metadata)
  File "/usr/lib/python3.10/email/parser.py", line 67, in parsestr
    return self.parse(StringIO(text), headersonly=headersonly)
  File "/usr/lib/python3.10/email/parser.py", line 56, in parse
    feedparser.feed(data)
  File "/usr/lib/python3.10/email/feedparser.py", line 175, in feed
    self._input.push(data)
  File "/usr/lib/python3.10/email/feedparser.py", line 110, in push
    parts = self._partial.readlines()
KeyboardInterrupt
During handling of the above exception, another exception occurred:
Traceback (most recent call last):
  File "/usr/local/bin/pip3", line 8, in <module>
    sys.exit(main())
  File "/usr/local/lib/python3.10/dist-packages/pip/_internal/cli/main.py", line 79, in main
    return command.main(cmd_args)
  File "/usr/local/lib/python3.10/dist-packages/pip/_internal/cli/base_command.py", line 101, in main
    return self._main(args)
  File "/usr/local/lib/python3.10/dist-packages/pip/_internal/cli/base_command.py", line 223, in _main
    return run(options, args)
  File "/usr/local/lib/python3.10/dist-packages/pip/_internal/cli/base_command.py", line 206, in exc_logging_wrapper
    logger.critical("Operation cancelled by user")
  File "/usr/lib/python3.10/logging/__init__.py", line 1524, in critical
    self._log(CRITICAL, msg, args, **kwargs)
  File "/usr/lib/python3.10/logging/__init__.py", line 1622, in _log
    record = self.makeRecord(self.name, level, fn, lno, msg, args,
  File "/usr/lib/python3.10/logging/__init__.py", line 1591, in makeRecord
    rv = _logRecordFactory(name, level, fn, lno, msg, args, exc_info, func,
  File "/usr/lib/python3.10/logging/__init__.py", line 283, in __init__
    def __init__(self, name, level, pathname, lineno,
KeyboardInterrupt
^C
Requirement already satisfied: sentencepiece in /usr/local/lib/python3.10/dist-packages (0.1.99)
Requirement already satisfied: pytz in /usr/local/lib/python3.10/dist-packages (2023.4)
Requirement already satisfied: fugashi[unidic-lite] in /usr/local/lib/python3.10/dist-packages (1.3.2)
Requirement already satisfied: unidic-lite in /usr/local/lib/python3.10/dist-packages (from fugashi[unidic-lite]) (1.0.8)
Requirement already satisfied: wandb in /usr/local/lib/python3.10/dist-packages (0.16.6)
Requirement already satisfied: Click!=8.0.0,>=7.1 in /usr/local/lib/python3.10/dist-packages (from wandb) (8.1.7)
Requirement already satisfied: GitPython!=3.1.29,>=1.0.0 in /usr/local/lib/python3.10/dist-packages (from wandb) (3.1.43)
Requirement already satisfied: requests<3,>=2.0.0 in /usr/local/lib/python3.10/dist-packages (from wandb) (2.31.0)
Requirement already satisfied: psutil>=5.0.0 in /usr/local/lib/python3.10/dist-packages (from wandb) (5.9.5)
Requirement already satisfied: sentry-sdk>=1.0.0 in /usr/local/lib/python3.10/dist-packages (from wandb) (2.0.1)
Requirement already satisfied: docker-pycreds>=0.4.0 in /usr/local/lib/python3.10/dist-packages (from wandb) (0.4.0)
Requirement already satisfied: PyYAML in /usr/local/lib/python3.10/dist-packages (from wandb) (6.0.1)
Requirement already satisfied: setproctitle in /usr/local/lib/python3.10/dist-packages (from wandb) (1.3.3)
Requirement already satisfied: setuptools in /usr/local/lib/python3.10/dist-packages (from wandb) (67.7.2)
Requirement already satisfied: appdirs>=1.4.3 in /usr/local/lib/python3.10/dist-packages (from wandb) (1.4.4)
Requirement already satisfied: protobuf!=4.21.0,<5,>=3.19.0 in /usr/local/lib/python3.10/dist-packages (from wandb) (3.20.3)
Requirement already satisfied: six>=1.4.0 in /usr/local/lib/python3.10/dist-packages (from docker-pycreds>=0.4.0->wandb) (1.16.0)
Requirement already satisfied: gitdb<5,>=4.0.1 in /usr/local/lib/python3.10/dist-packages (from GitPython!=3.1.29,>=1.0.0->wandb) (4.0.11)
Requirement already satisfied: charset-normalizer<4,>=2 in /usr/local/lib/python3.10/dist-packages (from requests<3,>=2.0.0->wandb) (3.3.2)
Requirement already satisfied: idna<4,>=2.5 in /usr/local/lib/python3.10/dist-packages (from requests<3,>=2.0.0->wandb) (3.7)
Requirement already satisfied: urllib3<3,>=1.21.1 in /usr/local/lib/python3.10/dist-packages (from requests<3,>=2.0.0->wandb) (2.0.7)
Requirement already satisfied: certifi>=2017.4.17 in /usr/local/lib/python3.10/dist-packages (from requests<3,>=2.0.0->wandb) (2024.2.2)
Requirement already satisfied: smmap<6,>=3.0.1 in /usr/local/lib/python3.10/dist-packages (from gitdb<5,>=4.0.1->GitPython!=3.1.29,>=1.0.0->wandb) (5.0.1)
[34m[1mwandb[39m[22m: [33mWARNING[39m Calling wandb.login() after wandb.init() has no effect.