Traceback (most recent call last):
  File "/home/takuma-s/Desktop/discourse_relation_explainability/.venv/lib/python3.12/site-packages/huggingface_hub/utils/_http.py", line 406, in hf_raise_for_status
    response.raise_for_status()
  File "/home/takuma-s/Desktop/discourse_relation_explainability/.venv/lib/python3.12/site-packages/requests/models.py", line 1024, in raise_for_status
    raise HTTPError(http_error_msg, response=self)
requests.exceptions.HTTPError: 404 Client Error: Not Found for url: https://huggingface.co/dummy/resolve/main/tokenizer_config.json
The above exception was the direct cause of the following exception:
Traceback (most recent call last):
  File "/home/takuma-s/Desktop/discourse_relation_explainability/.venv/lib/python3.12/site-packages/transformers/utils/hub.py", line 402, in cached_file
    resolved_file = hf_hub_download(
                    ^^^^^^^^^^^^^^^^
  File "/home/takuma-s/Desktop/discourse_relation_explainability/.venv/lib/python3.12/site-packages/huggingface_hub/utils/_validators.py", line 114, in _inner_fn
    return fn(*args, **kwargs)
           ^^^^^^^^^^^^^^^^^^^
  File "/home/takuma-s/Desktop/discourse_relation_explainability/.venv/lib/python3.12/site-packages/huggingface_hub/file_download.py", line 860, in hf_hub_download
    return _hf_hub_download_to_cache_dir(
           ^^^^^^^^^^^^^^^^^^^^^^^^^^^^^^
  File "/home/takuma-s/Desktop/discourse_relation_explainability/.venv/lib/python3.12/site-packages/huggingface_hub/file_download.py", line 967, in _hf_hub_download_to_cache_dir
    _raise_on_head_call_error(head_call_error, force_download, local_files_only)
  File "/home/takuma-s/Desktop/discourse_relation_explainability/.venv/lib/python3.12/site-packages/huggingface_hub/file_download.py", line 1482, in _raise_on_head_call_error
    raise head_call_error
  File "/home/takuma-s/Desktop/discourse_relation_explainability/.venv/lib/python3.12/site-packages/huggingface_hub/file_download.py", line 1374, in _get_metadata_or_catch_error
    metadata = get_hf_file_metadata(
               ^^^^^^^^^^^^^^^^^^^^^
  File "/home/takuma-s/Desktop/discourse_relation_explainability/.venv/lib/python3.12/site-packages/huggingface_hub/utils/_validators.py", line 114, in _inner_fn
    return fn(*args, **kwargs)
           ^^^^^^^^^^^^^^^^^^^
  File "/home/takuma-s/Desktop/discourse_relation_explainability/.venv/lib/python3.12/site-packages/huggingface_hub/file_download.py", line 1294, in get_hf_file_metadata
    r = _request_wrapper(
        ^^^^^^^^^^^^^^^^^
  File "/home/takuma-s/Desktop/discourse_relation_explainability/.venv/lib/python3.12/site-packages/huggingface_hub/file_download.py", line 278, in _request_wrapper
    response = _request_wrapper(
               ^^^^^^^^^^^^^^^^^
  File "/home/takuma-s/Desktop/discourse_relation_explainability/.venv/lib/python3.12/site-packages/huggingface_hub/file_download.py", line 302, in _request_wrapper
    hf_raise_for_status(response)
  File "/home/takuma-s/Desktop/discourse_relation_explainability/.venv/lib/python3.12/site-packages/huggingface_hub/utils/_http.py", line 454, in hf_raise_for_status
    raise _format(RepositoryNotFoundError, message, response) from e
huggingface_hub.errors.RepositoryNotFoundError: 404 Client Error. (Request ID: Root=1-67b1c4a9-0da52ccc40b832a67da36ce7;af5c730a-9e84-4471-beea-32115db74c8e)
Repository Not Found for url: https://huggingface.co/dummy/resolve/main/tokenizer_config.json.
Please make sure you specified the correct `repo_id` and `repo_type`.
If you are trying to access a private or gated repo, make sure you are authenticated.
The above exception was the direct cause of the following exception:
Traceback (most recent call last):
  File "/home/takuma-s/Desktop/discourse_relation_explainability/src/run_multiple_experiments.py", line 147, in <module>
    main()
  File "/home/takuma-s/Desktop/discourse_relation_explainability/src/run_multiple_experiments.py", line 122, in main
    all_label_metrics, by_label_metrics = fine_tuning_main(cfg)
                                          ^^^^^^^^^^^^^^^^^^^^^
  File "/home/takuma-s/Desktop/discourse_relation_explainability/src/fine_tuning.py", line 407, in main
    tokenizer, model = load_model_and_tokenizer(cfg.model_name, cfg.num_labels)
                       ^^^^^^^^^^^^^^^^^^^^^^^^^^^^^^^^^^^^^^^^^^^^^^^^^^^^^^^^
  File "/home/takuma-s/Desktop/discourse_relation_explainability/src/fine_tuning.py", line 47, in load_model_and_tokenizer
    tokenizer = AutoTokenizer.from_pretrained(model_name, word_tokenizer_type="mecab")
                ^^^^^^^^^^^^^^^^^^^^^^^^^^^^^^^^^^^^^^^^^^^^^^^^^^^^^^^^^^^^^^^^^^^^^^
  File "/home/takuma-s/Desktop/discourse_relation_explainability/.venv/lib/python3.12/site-packages/transformers/models/auto/tokenization_auto.py", line 826, in from_pretrained
    tokenizer_config = get_tokenizer_config(pretrained_model_name_or_path, **kwargs)
                       ^^^^^^^^^^^^^^^^^^^^^^^^^^^^^^^^^^^^^^^^^^^^^^^^^^^^^^^^^^^^^
  File "/home/takuma-s/Desktop/discourse_relation_explainability/.venv/lib/python3.12/site-packages/transformers/models/auto/tokenization_auto.py", line 658, in get_tokenizer_config
    resolved_config_file = cached_file(
                           ^^^^^^^^^^^^
  File "/home/takuma-s/Desktop/discourse_relation_explainability/.venv/lib/python3.12/site-packages/transformers/utils/hub.py", line 425, in cached_file
    raise EnvironmentError(
OSError: dummy is not a local folder and is not a valid model identifier listed on 'https://huggingface.co/models'
If this is a private repository, make sure to pass a token having permission to this repo either by logging in with `huggingface-cli login` or by passing `token=<your_token>`